2024-06-20 20:45:50,603 - WARNING - CheckTotalPrecipitation - Passage en mode Weather => precipation > seuil
2024-06-20 21:11:01,052 - WARNING - CheckTotalPrecipitation - Passage en mode Weather => precipation > seuil
2024-06-21 05:34:21,493 - ERROR - GetPrecipitationByDay - Erreur GetPrecipitationByDay
Traceback (most recent call last):
  File "/usr/lib/python3/dist-packages/urllib3/connection.py", line 162, in _new_conn
    (self._dns_host, self.port), self.timeout, **extra_kw)
  File "/usr/lib/python3/dist-packages/urllib3/util/connection.py", line 57, in create_connection
    for res in socket.getaddrinfo(host, port, family, socket.SOCK_STREAM):
  File "/usr/lib/python3.7/socket.py", line 748, in getaddrinfo
    for res in _socket.getaddrinfo(host, port, family, type, proto, flags):
socket.gaierror: [Errno -3] Temporary failure in name resolution

During handling of the above exception, another exception occurred:

Traceback (most recent call last):
  File "/usr/lib/python3/dist-packages/urllib3/connectionpool.py", line 601, in urlopen
    chunked=chunked)
  File "/usr/lib/python3/dist-packages/urllib3/connectionpool.py", line 344, in _make_request
    self._validate_conn(conn)
  File "/usr/lib/python3/dist-packages/urllib3/connectionpool.py", line 846, in _validate_conn
    conn.connect()
  File "/usr/lib/python3/dist-packages/urllib3/connection.py", line 315, in connect
    conn = self._new_conn()
  File "/usr/lib/python3/dist-packages/urllib3/connection.py", line 171, in _new_conn
    self, "Failed to establish a new connection: %s" % e)
urllib3.exceptions.NewConnectionError: <urllib3.connection.VerifiedHTTPSConnection object at 0x7267df30>: Failed to establish a new connection: [Errno -3] Temporary failure in name resolution

During handling of the above exception, another exception occurred:

Traceback (most recent call last):
  File "/usr/lib/python3/dist-packages/requests/adapters.py", line 449, in send
    timeout=timeout
  File "/usr/lib/python3/dist-packages/urllib3/connectionpool.py", line 639, in urlopen
    _stacktrace=sys.exc_info()[2])
  File "/usr/lib/python3/dist-packages/urllib3/util/retry.py", line 399, in increment
    raise MaxRetryError(_pool, url, error or ResponseError(cause))
urllib3.exceptions.MaxRetryError: HTTPSConnectionPool(host='api.openweathermap.org', port=443): Max retries exceeded with url: /data/3.0/onecall/day_summary?lat=43.82019499614341&lon=5.083383552048545&date=2024-06-21&appid=0624b9f5544bf3786af244248eba3d22&units=metric&lang=fr (Caused by NewConnectionError('<urllib3.connection.VerifiedHTTPSConnection object at 0x7267df30>: Failed to establish a new connection: [Errno -3] Temporary failure in name resolution'))

During handling of the above exception, another exception occurred:

Traceback (most recent call last):
  File "/home/pi/arrosage/function.py", line 769, in GetPrecipitationByDay
    lon=longitude))
  File "/usr/lib/python3/dist-packages/requests/api.py", line 75, in get
    return request('get', url, params=params, **kwargs)
  File "/usr/lib/python3/dist-packages/requests/api.py", line 60, in request
    return session.request(method=method, url=url, **kwargs)
  File "/usr/lib/python3/dist-packages/requests/sessions.py", line 535, in request
    resp = self.send(prep, **send_kwargs)
  File "/usr/lib/python3/dist-packages/requests/sessions.py", line 648, in send
    r = adapter.send(request, **kwargs)
  File "/usr/lib/python3/dist-packages/requests/adapters.py", line 516, in send
    raise ConnectionError(e, request=request)
requests.exceptions.ConnectionError: HTTPSConnectionPool(host='api.openweathermap.org', port=443): Max retries exceeded with url: /data/3.0/onecall/day_summary?lat=43.82019499614341&lon=5.083383552048545&date=2024-06-21&appid=0624b9f5544bf3786af244248eba3d22&units=metric&lang=fr (Caused by NewConnectionError('<urllib3.connection.VerifiedHTTPSConnection object at 0x7267df30>: Failed to establish a new connection: [Errno -3] Temporary failure in name resolution'))
2024-06-21 05:34:21,571 - ERROR - GetPrecipitationByDay - Erreur GetPrecipitationByDay
Traceback (most recent call last):
  File "/usr/lib/python3/dist-packages/urllib3/connection.py", line 162, in _new_conn
    (self._dns_host, self.port), self.timeout, **extra_kw)
  File "/usr/lib/python3/dist-packages/urllib3/util/connection.py", line 57, in create_connection
    for res in socket.getaddrinfo(host, port, family, socket.SOCK_STREAM):
  File "/usr/lib/python3.7/socket.py", line 748, in getaddrinfo
    for res in _socket.getaddrinfo(host, port, family, type, proto, flags):
socket.gaierror: [Errno -3] Temporary failure in name resolution

During handling of the above exception, another exception occurred:

Traceback (most recent call last):
  File "/usr/lib/python3/dist-packages/urllib3/connectionpool.py", line 601, in urlopen
    chunked=chunked)
  File "/usr/lib/python3/dist-packages/urllib3/connectionpool.py", line 344, in _make_request
    self._validate_conn(conn)
  File "/usr/lib/python3/dist-packages/urllib3/connectionpool.py", line 846, in _validate_conn
    conn.connect()
  File "/usr/lib/python3/dist-packages/urllib3/connection.py", line 315, in connect
    conn = self._new_conn()
  File "/usr/lib/python3/dist-packages/urllib3/connection.py", line 171, in _new_conn
    self, "Failed to establish a new connection: %s" % e)
urllib3.exceptions.NewConnectionError: <urllib3.connection.VerifiedHTTPSConnection object at 0x7267dc50>: Failed to establish a new connection: [Errno -3] Temporary failure in name resolution

During handling of the above exception, another exception occurred:

Traceback (most recent call last):
  File "/usr/lib/python3/dist-packages/requests/adapters.py", line 449, in send
    timeout=timeout
  File "/usr/lib/python3/dist-packages/urllib3/connectionpool.py", line 639, in urlopen
    _stacktrace=sys.exc_info()[2])
  File "/usr/lib/python3/dist-packages/urllib3/util/retry.py", line 399, in increment
    raise MaxRetryError(_pool, url, error or ResponseError(cause))
urllib3.exceptions.MaxRetryError: HTTPSConnectionPool(host='api.openweathermap.org', port=443): Max retries exceeded with url: /data/3.0/onecall/day_summary?lat=43.82019499614341&lon=5.083383552048545&date=2024-06-20&appid=0624b9f5544bf3786af244248eba3d22&units=metric&lang=fr (Caused by NewConnectionError('<urllib3.connection.VerifiedHTTPSConnection object at 0x7267dc50>: Failed to establish a new connection: [Errno -3] Temporary failure in name resolution'))

During handling of the above exception, another exception occurred:

Traceback (most recent call last):
  File "/home/pi/arrosage/function.py", line 769, in GetPrecipitationByDay
    lon=longitude))
  File "/usr/lib/python3/dist-packages/requests/api.py", line 75, in get
    return request('get', url, params=params, **kwargs)
  File "/usr/lib/python3/dist-packages/requests/api.py", line 60, in request
    return session.request(method=method, url=url, **kwargs)
  File "/usr/lib/python3/dist-packages/requests/sessions.py", line 535, in request
    resp = self.send(prep, **send_kwargs)
  File "/usr/lib/python3/dist-packages/requests/sessions.py", line 648, in send
    r = adapter.send(request, **kwargs)
  File "/usr/lib/python3/dist-packages/requests/adapters.py", line 516, in send
    raise ConnectionError(e, request=request)
requests.exceptions.ConnectionError: HTTPSConnectionPool(host='api.openweathermap.org', port=443): Max retries exceeded with url: /data/3.0/onecall/day_summary?lat=43.82019499614341&lon=5.083383552048545&date=2024-06-20&appid=0624b9f5544bf3786af244248eba3d22&units=metric&lang=fr (Caused by NewConnectionError('<urllib3.connection.VerifiedHTTPSConnection object at 0x7267dc50>: Failed to establish a new connection: [Errno -3] Temporary failure in name resolution'))
2024-06-21 05:34:22,022 - INFO - CheckTotalPrecipitation - Passage en mode auto => precipation < seuil
2024-06-21 05:39:24,431 - WARNING - CheckTotalPrecipitation - Passage en mode Weather => precipation > seuil
2024-06-22 00:01:26,687 - INFO - CheckTotalPrecipitation - Passage en mode auto => precipation < seuil
2024-06-22 14:49:24,507 - WARNING - CheckTotalPrecipitation - Passage en mode Weather => precipation > seuil
2024-06-22 16:10:07,705 - ERROR - GetPrecipitationByDay - Erreur GetPrecipitationByDay
Traceback (most recent call last):
  File "/home/pi/arrosage/function.py", line 766, in GetPrecipitationByDay
    weather_data = json.loads(weather_history.content.decode('utf-8'))
  File "/usr/lib/python3.7/json/__init__.py", line 348, in loads
    return _default_decoder.decode(s)
  File "/usr/lib/python3.7/json/decoder.py", line 337, in decode
    obj, end = self.raw_decode(s, idx=_w(s, 0).end())
  File "/usr/lib/python3.7/json/decoder.py", line 355, in raw_decode
    raise JSONDecodeError("Expecting value", s, err.value) from None
json.decoder.JSONDecodeError: Expecting value: line 1 column 1 (char 0)
2024-06-22 16:10:08,184 - INFO - CheckTotalPrecipitation - Passage en mode auto => precipation < seuil
2024-06-22 16:15:11,038 - WARNING - CheckTotalPrecipitation - Passage en mode Weather => precipation > seuil
